<mujoco model="MPL_left(v1.31)">
    <!--
    This file and the .stl mesh files referenced from it have been derived by Roboti LLC from the model of the Modular Prosthetic Limb developed by The Johns Hopkins University / Applied Physics Laboratory. The modifications are as follows: the original meshes have been replaced with their convex hulls; the original URDF model has been converted to the MJCF format and a number of MJCF-specific fields have been added.

    The Johns Hopkins University / Applied Physics Laboratory has given Roboti LLC permission to distribute the modified model under the following license:

    =========================

    (C) 2013 The Johns Hopkins University / Applied Physics Laboratory All Rights Reserved.

    Licensed under the Apache License, Version 2.0 (the "License"); you may not use this file except in compliance with the License. You may obtain a copy of the License at

    http://www.apache.org/licenses/LICENSE-2.0

    Unless required by applicable law or agreed to in writing, software distributed under the License is distributed on an "AS IS" BASIS, WITHOUT WARRANTIES OR CONDITIONS OF ANY KIND, either express or implied. See the License for the specific language governing permissions and limitations under the License.

    ========================

    The modifications made by Roboti LLC are also licensed under the Apache License version 2.0.
    -->
    <compiler angle="radian" meshdir="../meshes/mesh_left" texturedir="../texture"/>
    <option apirate="50" iterations="50"/>
    <size njmax="600" nconmax="150" nstack="300000"/>
    <visual>
        <quality shadowsize="2048"/>
        <headlight diffuse="0.6 0.6 0.6" specular="0 0 0"/>
        <map fogstart="6"/>
    </visual>
    <default class="main">
        <default class="MPL">
            <joint limited="true" armature="0.01" damping="0.2"/>
            <geom condim="4" margin="0.001" material="MatMesh"/>
            <site group="3" type="ellipsoid" material="MatTouch"/>
            <general ctrllimited="true" biastype="affine" gainprm="10 0 0 0 0 0 0 0 0 0" biasprm="0 -10 0 0 0 0 0 0 0 0"/>
        </default>
        <default class="IMU">
            <site group="4" type="box" material="MatIMU"/>
        </default>
        <default class="free">
            <joint type="free"/>
        </default>
    </default>
    <asset>
        <texture type="skybox" builtin="gradient" rgb1="0.4 0.6 0.8" rgb2="0 0 0" width="100" height="600"/>
        <texture type="2d" name="groundplane" builtin="checker" rgb1="0.2 0.3 0.4" rgb2="0.1 0.2 0.3" markrgb="0.8 0.8 0.8" width="100" height="100"/>
        <texture type="cube" name="skin" file="skin.png"/>
        <material name="MatTouch" rgba="0.3 0.9 0.3 0.3"/>
        <material name="MatIMU" rgba="0.1 0.1 0.9 1"/>
        <material name="MatMesh" texture="skin"/>
        <mesh name="index0" file="index0_left.stl"/>
        <mesh name="index1" file="index1_left.stl"/>
        <mesh name="index2" file="index2_left.stl"/>
        <mesh name="index3" file="index3_left.stl"/>
        <mesh name="middle0" file="middle0_left.stl"/>
        <mesh name="middle1" file="middle1_left.stl"/>
        <mesh name="middle2" file="middle2_left.stl"/>
        <mesh name="middle3" file="middle3_left.stl"/>
        <mesh name="palm" file="palm_left.stl"/>
        <mesh name="pinky0" file="pinky0_left.stl"/>
        <mesh name="pinky1" file="pinky1_left.stl"/>
        <mesh name="pinky2" file="pinky2_left.stl"/>
        <mesh name="pinky3" file="pinky3_left.stl"/>
        <mesh name="ring0" file="ring0_left.stl"/>
        <mesh name="ring1" file="ring1_left.stl"/>
        <mesh name="ring2" file="ring2_left.stl"/>
        <mesh name="ring3" file="ring3_left.stl"/>
        <mesh name="thumb0" file="thumb0_left.stl"/>
        <mesh name="thumb1" file="thumb1_left.stl"/>
        <mesh name="thumb2" file="thumb2_left.stl"/>
        <mesh name="thumb3" file="thumb3_left.stl"/>
        <mesh name="wristx" file="wristx_left.stl"/>
        <mesh name="wristy" file="wristy_left.stl"/>
        <mesh name="wristz" file="wristz_left.stl"/>
    </asset>
    <worldbody>
        <body name="forearm" childclass="MPL" pos="0 0 0">
            <geom size="0.02 0.01" quat="0.707107 -0.707107 0 0" type="cylinder"/>
            <body name="wristy" pos="0 0 0">
                <inertial pos="7.08369e-05 -0.0217787 -0.000286168" quat="0.707488 0.00581744 -0.0107421 0.70662" mass="0.0272932" diaginertia="2.46813e-05 1.77029e-05 1.71079e-05"/>
                <joint name="wrist_PRO" pos="0 0 0" axis="0 1 0" range="-1.57 1.57" damping="0.4"/>
                <geom type="mesh" mesh="wristy"/>
                <body name="wristx" pos="3.36826e-05 -0.0476452 0.00203763">
                    <inertial pos="-0.00139174 -0.00975189 -0.00252668" quat="-0.0729226 0.705959 0.0352732 0.703605" mass="0.010691" diaginertia="5.04455e-06 4.25035e-06 3.25677e-06"/>
                    <joint name="wrist_UDEV" pos="0 0 0" axis="0 0 -1" range="-0.261 0.785" damping="0.4"/>
                    <geom type="mesh" mesh="wristx"/>
                    <body name="wristz" pos="-0.0001872 -0.03 -0.002094">
                        <inertial pos="-0.000579016 -0.00125952 0.000455968" quat="0.527723 0.475346 0.521597 0.472749" mass="0.00602247" diaginertia="1.58133e-06 1.43102e-06 1.26861e-06"/>
                        <joint name="wrist_FLEX" pos="0 0 0" axis="1 0 0" range="-1.04 1.04" damping="0.4"/>
                        <geom type="mesh" mesh="wristz"/>
                        <body name="palm" pos="-0.025625 0 0">
                            <inertial pos="0.0217876 -0.0376147 0.00276997" quat="0.157073 0.657733 -0.154839 0.720236" mass="0.119867" diaginertia="0.000123088 0.000100082 6.89467e-05"/>
                            <geom type="mesh" mesh="palm"/>
                            <site name="palm_thumb" pos="0.0052 -0.0438 -0.0182" size="0.017 0.03 0.01"/>
                            <site name="palm_pinky" pos="0.0358 -0.0401 -0.0183" size="0.017 0.03 0.01"/>
                            <site name="palm_side" pos="0.0604 -0.0329 -0.0048" size="0.01 0.03 0.015"/>
                            <site name="palm_back" pos="0.0246 -0.0446 0.018" size="0.03 0.035 0.015"/>
                            <body name="thumb0" pos="-0.00835752 -0.0206978 -0.010093" quat="0.990237 -0.0412644 0.0209178 0.13149">
                                <inertial pos="-0.00863339 -0.000156884 -0.000945846" quat="0.408795 0.551643 0.541079 0.485602" mass="0.00336696" diaginertia="4.50769e-07 4.48758e-07 2.35017e-07"/>
                                <joint name="thumb_ABD" pos="0 0 0" axis="0 -1 0" range="0 2.07"/>
                                <geom type="mesh" mesh="thumb0"/>
                                <body name="thumb1" pos="-0.0209172 -0.00084 0.0014476">
                                    <inertial pos="-0.019024 0.000361131 -0.000186763" quat="0.5208 0.469572 0.484571 0.522934" mass="0.00596213" diaginertia="9.88001e-07 9.45125e-07 5.32989e-07"/>
                                    <joint name="thumb_MCP" pos="0 0 0" axis="0 0 1" range="0 1.03"/>
                                    <geom type="mesh" mesh="thumb1"/>
                                    <site name="thumb_proximal" pos="-0.0173 -0.008 0.0009" size="0.015 0.0075 0.01"/>
                                    <body name="thumb2" pos="-0.0335 0 -0.0007426">
                                        <inertial pos="-0.0188965 0.000375725 0.00065381" quat="0.502274 0.484638 0.475673 0.535333" mass="0.00599792" diaginertia="9.96692e-07 9.64948e-07 5.14416e-07"/>
                                        <joint name="thumb_PIP" pos="0 0 0" axis="0 0 1" range="0 1.03"/>
                                        <geom type="mesh" mesh="thumb2"/>
                                        <site name="thumb_medial" pos="-0.0182 -0.008 0.0015" size="0.015 0.0075 0.01"/>
                                        <body name="thumb3" pos="-0.0335 0 0.0010854">
                                            <inertial pos="-0.0188965 0.000375725 0.00065381" quat="0.502274 0.484638 0.475673 0.535333" mass="0.00599792" diaginertia="9.96692e-07 9.64948e-07 5.14416e-07"/>
                                            <joint name="thumb_DIP" pos="0 0 0" axis="0 0 1" range="-0.819 1.28"/>
                                            <geom type="mesh" mesh="thumb3"/>
                                            <site name="thumb_distal" pos="-0.0156 -0.007 0.0003" quat="0.995004 0 0 -0.0998334" size="0.015 0.0075 0.01"/>
                                            <site name="thumb_IMU" class="IMU" pos="-0.0099 -0.00052 0" quat="0.5 0.5 0.5 0.5" size="0.003 0.003 0.003"/>
                                        </body>
                                    </body>
                                </body>
                            </body>
                            <body name="index0" pos="-0.00986485 -0.0658 0.00101221" quat="0.996195 0 -0.0871557 0">
                                <inertial pos="0.000142572 -0.00548494 0.000206145" quat="0.699132 0.714861 -0.000723869 0.013694" mass="0.00295579" diaginertia="4.22462e-07 4.02281e-07 1.93868e-07"/>
                                <joint name="index_ABD" pos="0 0 0" axis="0 0 -1" range="0 0.345"/>
                                <geom type="mesh" mesh="index0"/>
                                <body name="index1" pos="-6.26e-05 -0.018 0">
                                    <inertial pos="-0.000406487 -0.0213125 0.000655609" quat="0.698452 0.715642 -0.00415384 0.0023049" mass="0.00478235" diaginertia="8.18599e-07 7.95693e-07 3.06254e-07"/>
                                    <joint name="index_MCP" pos="0 0 0" axis="1 0 0" range="-0.785 1.57"/>
                                    <geom type="mesh" mesh="index1"/>
                                    <site name="index_proximal" pos="0 -0.0235 -0.007" size="0.009 0.015 0.0075"/>
                                    <body name="index2" pos="-0.001086 -0.0435 0.0005">
                                        <inertial pos="0.000841462 -0.012689 0.000572665" quat="0.734882 0.677481 -0.028511 0.0124827" mass="0.00344764" diaginertia="3.63962e-07 3.59059e-07 1.05304e-07"/>
                                        <joint name="index_PIP" pos="0 0 0" axis="1 0 0" range="0 1.72"/>
                                        <geom type="mesh" mesh="index2"/>
                                        <site name="index_medial" pos="0 -0.009 -0.0047" size="0.0075 0.01 0.006"/>
                                        <body name="index3" pos="0.000635 -0.0245 0">
                                            <inertial pos="-4.32004e-05 -0.0125318 0.000903476" quat="0.516251 0.4829 -0.483241 0.516498" mass="0.00274415" diaginertia="1.19635e-07 1.09202e-07 7.77873e-08"/>
                                            <joint name="index_DIP" pos="0 0 0" axis="1 0 0" range="0 1.38"/>
                                            <geom type="mesh" mesh="index3"/>
                                            <site name="index_distal" pos="0 -0.0132 -0.0038" size="0.0075 0.01 0.006"/>
                                            <site name="index_IMU" class="IMU" pos="0 -0.0093 0.00063" quat="0.5 0.5 -0.5 0.5" size="0.003 0.003 0.003"/>
                                        </body>
                                    </body>
                                </body>
                            </body>
                            <body name="middle0" pos="0.012814 -0.0779014 0.00544608" quat="0.999904 -0.0138902 0 0">
                                <inertial pos="0.000142567 -0.00548493 0.000206162" quat="0.699131 0.714862 -0.000723874 0.013694" mass="0.00295579" diaginertia="4.22461e-07 4.02281e-07 1.93868e-07"/>
                                <geom type="mesh" mesh="middle0"/>
                                <body name="middle1" pos="-6.26e-05 -0.018 0">
                                    <inertial pos="-0.000406411 -0.0213125 0.00065565" quat="0.698451 0.715642 -0.00415503 0.00230486" mass="0.00478229" diaginertia="8.18595e-07 7.9569e-07 3.06253e-07"/>
                                    <joint name="middle_MCP" pos="0 0 0" axis="1 0 0" range="-0.785 1.57"/>
                                    <geom type="mesh" mesh="middle1"/>
                                    <site name="middle_proximal" pos="0 -0.025 -0.007" size="0.009 0.015 0.0075"/>
                                    <body name="middle2" pos="-0.001086 -0.0435 0.0005">
                                        <inertial pos="0.000841444 -0.012689 0.00057266" quat="0.734883 0.677482 -0.0284727 0.0124412" mass="0.00344765" diaginertia="3.63962e-07 3.5906e-07 1.05304e-07"/>
                                        <joint name="middle_PIP" pos="0 0 0" axis="1 0 0" range="0 1.73"/>
                                        <geom type="mesh" mesh="middle2"/>
                                        <site name="middle_medial" pos="0 -0.0146 -0.0047" size="0.0075 0.01 0.006"/>
                                        <body name="middle3" pos="0.000635 -0.0245 0">
                                            <inertial pos="-4.31236e-05 -0.0125318 0.000903446" quat="0.516263 0.482913 -0.483228 0.516487" mass="0.00274417" diaginertia="1.19635e-07 1.09202e-07 7.77884e-08"/>
                                            <joint name="middle_DIP" pos="0 0 0" axis="1 0 0" range="0 1.38"/>
                                            <geom type="mesh" mesh="middle3"/>
                                            <site name="middle_distal" pos="0 -0.0129 -0.0038" size="0.0075 0.01 0.006"/>
                                            <site name="middle_IMU" class="IMU" pos="0 -0.0093 0.00063" quat="0.5 0.5 -0.5 0.5" size="0.003 0.003 0.003"/>
                                        </body>
                                    </body>
                                </body>
                            </body>
                            <body name="ring0" pos="0.0354928 -0.0666999 0.00151221" quat="0.996195 0 0.0871557 0">
                                <inertial pos="0.000142559 -0.00548494 0.000206147" quat="0.699132 0.714861 -0.000720946 0.013691" mass="0.00295579" diaginertia="4.22462e-07 4.02281e-07 1.93868e-07"/>
                                <joint name="ring_ABD" pos="0 0 0" axis="0 0 1" range="0 0.345"/>
                                <geom type="mesh" mesh="ring0"/>
                                <body name="ring1" pos="-6.26e-05 -0.018 0">
                                    <inertial pos="-0.000406447 -0.0213125 0.00065563" quat="0.698451 0.715642 -0.00415675 0.00230715" mass="0.00478232" diaginertia="8.18597e-07 7.95692e-07 3.06254e-07"/>
                                    <joint name="ring_MCP" pos="0 0 0" axis="1 0 0" range="-0.785 1.57"/>
                                    <geom type="mesh" mesh="ring1"/>
                                    <site name="ring_proximal" pos="0 -0.0259 -0.007" size="0.009 0.015 0.0075"/>
                                    <body name="ring2" pos="-0.001086 -0.0435 0.0005">
                                        <inertial pos="0.000841518 -0.012689 0.000572674" quat="0.73488 0.677478 -0.0285773 0.0125557" mass="0.00344767" diaginertia="3.63963e-07 3.59061e-07 1.05305e-07"/>
                                        <joint name="ring_PIP" pos="0 0 0" axis="1 0 0" range="0 1.72"/>
                                        <geom type="mesh" mesh="ring2"/>
                                        <site name="ring_medial" pos="0 -0.0137 -0.0047" size="0.0075 0.01 0.006"/>
                                        <body name="ring3" pos="0.000635 -0.0245 0">
                                            <inertial pos="-4.31973e-05 -0.0125318 0.000903457" quat="0.516255 0.482902 -0.483238 0.516495" mass="0.00274416" diaginertia="1.19635e-07 1.09202e-07 7.77877e-08"/>
                                            <joint name="ring_DIP" pos="0 0 0" axis="1 0 0" range="0 1.38"/>
                                            <geom type="mesh" mesh="ring3"/>
                                            <site name="ring_distal" pos="0 -0.0117 -0.0038" size="0.0075 0.01 0.006"/>
                                            <site name="ring_IMU" class="IMU" pos="0 -0.0093 0.00063" quat="0.5 0.5 -0.5 0.5" size="0.003 0.003 0.003"/>
                                        </body>
                                    </body>
                                </body>
                            </body>
                            <body name="pinky0" pos="0.0562459 -0.0554001 -0.00563858" quat="0.996195 0 0.0871557 0">
                                <inertial pos="0.000142559 -0.00538484 0.000206147" quat="0.699132 0.714861 -0.000721037 0.0136911" mass="0.00295579" diaginertia="4.22462e-07 4.02281e-07 1.93868e-07"/>
                                <joint name="pinky_ABD" pos="0 0 0" axis="0 0 1" range="0 0.345"/>
                                <geom type="mesh" mesh="pinky0"/>
                                <body name="pinky1" pos="-6.26e-05 -0.0178999 0">
                                    <inertial pos="-0.000458624 -0.0160478 0.000924735" quat="0.685529 0.72723 0.021252 -0.0270914" mass="0.0034099" diaginertia="4.03391e-07 3.84061e-07 2.19866e-07"/>
                                    <joint name="pinky_MCP" pos="0 0 0" axis="1 0 0" range="-0.785 1.57"/>
                                    <geom type="mesh" mesh="pinky1"/>
                                    <site name="pinky_proximal" pos="0 -0.021 -0.0066" size="0.009 0.013 0.0075"/>
                                    <body name="pinky2" pos="-0.000578 -0.033 0.0005">
                                        <inertial pos="0.000270832 -0.00914628 0.000738493" quat="0.746786 0.664476 -4.11065e-05 -0.0279675" mass="0.00250622" diaginertia="1.79089e-07 1.75934e-07 7.44543e-08"/>
                                        <joint name="pinky_PIP" pos="0 0 0" axis="1 0 0" range="0 1.72"/>
                                        <geom type="mesh" mesh="pinky2"/>
                                        <site name="pinky_medial" pos="0 -0.0117 -0.0047" size="0.0075 0.01 0.006"/>
                                        <body name="pinky3" pos="4.78e-05 -0.0175 0">
                                            <inertial pos="-3.85026e-05 -0.0125047 0.000912295" quat="0.516037 0.484447 -0.483043 0.515448" mass="0.00273265" diaginertia="1.19141e-07 1.08629e-07 7.77271e-08"/>
                                            <joint name="pinky_DIP" pos="0 0 0" axis="1 0 0" range="0 1.38"/>
                                            <geom type="mesh" mesh="pinky3"/>
                                            <site name="pinky_distal" pos="0 -0.0121 -0.0038" size="0.0075 0.01 0.006"/>
                                            <site name="pinky_IMU" class="IMU" pos="0 -0.0093 0.00063" quat="0.5 0.5 -0.5 0.5" size="0.003 0.003 0.003"/>
                                        </body>
                                    </body>
                                </body>
                            </body>
                        </body>
                    </body>
                </body>
            </body>
        </body>
    </worldbody>
    <contact>
        <exclude body1="wristy" body2="wristz"/>
        <exclude body1="wristx" body2="thumb0"/>
        <exclude body1="palm" body2="thumb1"/>
        <exclude body1="palm" body2="index1"/>
        <exclude body1="palm" body2="middle1"/>
        <exclude body1="palm" body2="ring1"/>
        <exclude body1="palm" body2="pinky1"/>
    </contact>
    <equality>
        <tendon name="E_index32_cpl" tendon1="T_index32_cpl" polycoef="0 1 0 0 0"/>
        <tendon name="E_index21_cpl" tendon1="T_index21_cpl" polycoef="0 1 0 0 0"/>
        <tendon name="E_middle32_cpl" tendon1="T_middle32_cpl" polycoef="0 1 0 0 0"/>
        <tendon name="E_middle21_cpl" tendon1="T_middle21_cpl" polycoef="0 1 0 0 0"/>
        <tendon name="E_ring32_cpl" tendon1="T_ring32_cpl" polycoef="0 1 0 0 0"/>
        <tendon name="E_ring21_cpl" tendon1="T_ring21_cpl" polycoef="0 1 0 0 0"/>
        <tendon name="E_pinky32_cpl" tendon1="T_pinky32_cpl" polycoef="0 1 0 0 0"/>
        <tendon name="E_pinky21_cpl" tendon1="T_pinky21_cpl" polycoef="0 1 0 0 0"/>
        <joint name="ring_pinky_cpl" joint1="ring_ABD" joint2="pinky_ABD" polycoef="0 0.5 0 0 0"/>
    </equality>
    <tendon>
        <fixed name="T_index32_cpl" range="0 1">
            <joint joint="index_DIP" coef="0.00705"/>
            <joint joint="index_PIP" coef="-0.00805"/>
        </fixed>
        <fixed name="T_index21_cpl" range="0 1">
            <joint joint="index_PIP" coef="0.01"/>
            <joint joint="index_MCP" coef="-0.01"/>
        </fixed>
        <fixed name="T_middle32_cpl">
            <joint joint="middle_DIP" coef="0.00705"/>
            <joint joint="middle_PIP" coef="-0.00805"/>
        </fixed>
        <fixed name="T_middle21_cpl">
            <joint joint="middle_PIP" coef="0.01"/>
            <joint joint="middle_MCP" coef="-0.01"/>
        </fixed>
        <fixed name="T_ring32_cpl">
            <joint joint="ring_DIP" coef="0.00705"/>
            <joint joint="ring_PIP" coef="-0.00805"/>
        </fixed>
        <fixed name="T_ring21_cpl">
            <joint joint="ring_PIP" coef="0.01"/>
            <joint joint="ring_MCP" coef="-0.01"/>
        </fixed>
        <fixed name="T_pinky32_cpl">
            <joint joint="pinky_DIP" coef="0.00705"/>
            <joint joint="pinky_PIP" coef="-0.00805"/>
        </fixed>
        <fixed name="T_pinky21_cpl">
            <joint joint="pinky_PIP" coef="0.01"/>
            <joint joint="pinky_MCP" coef="-0.01"/>
        </fixed>
    </tendon>
    <actuator>
        <general name="A_wrist_PRO" class="MPL" joint="wrist_PRO" ctrlrange="-1.57 1.57"/>
        <general name="A_wrist_UDEV" class="MPL" joint="wrist_UDEV" ctrlrange="-0.26 0.79"/>
        <general name="A_wrist_FLEX" class="MPL" joint="wrist_FLEX" ctrlrange="-1 1"/>
        <general name="A_thumb_ABD" class="MPL" joint="thumb_ABD" ctrlrange="0 2.1"/>
        <general name="A_thumb_MCP" class="MPL" joint="thumb_MCP" ctrlrange="0 1"/>
        <general name="A_thumb_PIP" class="MPL" joint="thumb_PIP" ctrlrange="0 1"/>
        <general name="A_thumb_DIP" class="MPL" joint="thumb_DIP" ctrlrange="-0.82 1.3"/>
        <general name="A_index_ABD" class="MPL" joint="index_ABD" ctrlrange="0 0.34"/>
        <general name="A_index_MCP" class="MPL" joint="index_MCP" ctrlrange="0 1.6"/>
        <general name="A_middle_MCP" class="MPL" joint="middle_MCP" ctrlrange="0 1.6"/>
        <general name="A_ring_MCP" class="MPL" joint="ring_MCP" ctrlrange="0 1.6"/>
        <general name="A_pinky_ABD" class="MPL" joint="pinky_ABD" ctrlrange="0 0.34"/>
        <general name="A_pinky_MCP" class="MPL" joint="pinky_MCP" ctrlrange="0 1.6"/>
    </actuator>
    <sensor>
        <jointpos joint="wrist_PRO" name="Sjp_wrist_PRO"/>
        <jointpos joint="wrist_UDEV" name="Sjp_wrist_UDEV"/>
        <jointpos joint="wrist_FLEX" name="Sjp_wrist_FLEX"/>
        <jointpos joint="thumb_ABD" name="Sjp_thumb_ABD"/>
        <jointpos joint="thumb_MCP" name="Sjp_thumb_MCP"/>
        <jointpos joint="thumb_PIP" name="Sjp_thumb_PIP"/>
        <jointpos joint="thumb_DIP" name="Sjp_thumb_DIP"/>
        <jointpos joint="index_ABD" name="Sjp_index_ABD"/>
        <jointpos joint="index_MCP" name="Sjp_index_MCP"/>
        <jointpos joint="index_PIP" name="Sjp_index_PIP"/>
        <jointpos joint="index_DIP" name="Sjp_index_DIP"/>
        <jointpos joint="middle_MCP" name="Sjp_middle_MCP"/>
        <jointpos joint="middle_PIP" name="Sjp_middle_PIP"/>
        <jointpos joint="middle_DIP" name="Sjp_middle_DIP"/>
        <jointpos joint="ring_ABD" name="Sjp_ring_ABD"/>
        <jointpos joint="ring_MCP" name="Sjp_ring_MCP"/>
        <jointpos joint="ring_PIP" name="Sjp_ring_PIP"/>
        <jointpos joint="ring_DIP" name="Sjp_ring_DIP"/>
        <jointpos joint="pinky_ABD" name="Sjp_pinky_ABD"/>
        <jointpos joint="pinky_MCP" name="Sjp_pinky_MCP"/>
        <jointpos joint="pinky_PIP" name="Sjp_pinky_PIP"/>
        <jointpos joint="pinky_DIP" name="Sjp_pinky_DIP"/>
        <jointvel joint="wrist_PRO" name="Sjv_wrist_PRO"/>
        <jointvel joint="wrist_UDEV" name="Sjv_wrist_UDEV"/>
        <jointvel joint="wrist_FLEX" name="Sjv_wrist_FLEX"/>
        <jointvel joint="thumb_ABD" name="Sjv_thumb_ABD"/>
        <jointvel joint="thumb_MCP" name="Sjv_thumb_MCP"/>
        <jointvel joint="thumb_PIP" name="Sjv_thumb_PIP"/>
        <jointvel joint="thumb_DIP" name="Sjv_thumb_DIP"/>
        <jointvel joint="index_ABD" name="Sjv_index_ABD"/>
        <jointvel joint="index_MCP" name="Sjv_index_MCP"/>
        <jointvel joint="index_PIP" name="Sjv_index_PIP"/>
        <jointvel joint="index_DIP" name="Sjv_index_DIP"/>
        <jointvel joint="middle_MCP" name="Sjv_middle_MCP"/>
        <jointvel joint="middle_PIP" name="Sjv_middle_PIP"/>
        <jointvel joint="middle_DIP" name="Sjv_middle_DIP"/>
        <jointvel joint="ring_ABD" name="Sjv_ring_ABD"/>
        <jointvel joint="ring_MCP" name="Sjv_ring_MCP"/>
        <jointvel joint="ring_PIP" name="Sjv_ring_PIP"/>
        <jointvel joint="ring_DIP" name="Sjv_ring_DIP"/>
        <jointvel joint="pinky_ABD" name="Sjv_pinky_ABD"/>
        <jointvel joint="pinky_MCP" name="Sjv_pinky_MCP"/>
        <jointvel joint="pinky_PIP" name="Sjv_pinky_PIP"/>
        <jointvel joint="pinky_DIP" name="Sjv_pinky_DIP"/>
        <actuatorpos actuator="A_wrist_PRO" name="Sap_wrist_PRO"/>
        <actuatorpos actuator="A_wrist_UDEV" name="Sap_wrist_UDEV"/>
        <actuatorpos actuator="A_wrist_FLEX" name="Sap_wrist_FLEX"/>
        <actuatorpos actuator="A_thumb_ABD" name="Sap_thumb_ABD"/>
        <actuatorpos actuator="A_thumb_MCP" name="Sap_thumb_MCP"/>
        <actuatorpos actuator="A_thumb_PIP" name="Sap_thumb_PIP"/>
        <actuatorpos actuator="A_thumb_DIP" name="Sap_thumb_DIP"/>
        <actuatorpos actuator="A_index_ABD" name="Sap_index_ABD"/>
        <actuatorpos actuator="A_index_MCP" name="Sap_index_MCP"/>
        <actuatorpos actuator="A_middle_MCP" name="Sap_middle_MCP"/>
        <actuatorpos actuator="A_ring_MCP" name="Sap_ring_MCP"/>
        <actuatorpos actuator="A_pinky_ABD" name="Sap_pinky_ABD"/>
        <actuatorpos actuator="A_pinky_MCP" name="Sap_pinky_MCP"/>
        <actuatorvel actuator="A_wrist_PRO" name="Sav_wrist_PRO"/>
        <actuatorvel actuator="A_wrist_UDEV" name="Sav_wrist_UDEV"/>
        <actuatorvel actuator="A_wrist_FLEX" name="Sav_wrist_FLEX"/>
        <actuatorvel actuator="A_thumb_ABD" name="Sav_thumb_ABD"/>
        <actuatorvel actuator="A_thumb_MCP" name="Sav_thumb_MCP"/>
        <actuatorvel actuator="A_thumb_PIP" name="Sav_thumb_PIP"/>
        <actuatorvel actuator="A_thumb_DIP" name="Sav_thumb_DIP"/>
        <actuatorvel actuator="A_index_ABD" name="Sav_index_ABD"/>
        <actuatorvel actuator="A_index_MCP" name="Sav_index_MCP"/>
        <actuatorvel actuator="A_middle_MCP" name="Sav_middle_MCP"/>
        <actuatorvel actuator="A_ring_MCP" name="Sav_ring_MCP"/>
        <actuatorvel actuator="A_pinky_ABD" name="Sav_pinky_ABD"/>
        <actuatorvel actuator="A_pinky_MCP" name="Sav_pinky_MCP"/>
        <actuatorfrc actuator="A_wrist_PRO" name="Saf_wrist_PRO"/>
        <actuatorfrc actuator="A_wrist_UDEV" name="Saf_wrist_UDEV"/>
        <actuatorfrc actuator="A_wrist_FLEX" name="Saf_wrist_FLEX"/>
        <actuatorfrc actuator="A_thumb_ABD" name="Saf_thumb_ABD"/>
        <actuatorfrc actuator="A_thumb_MCP" name="Saf_thumb_MCP"/>
        <actuatorfrc actuator="A_thumb_PIP" name="Saf_thumb_PIP"/>
        <actuatorfrc actuator="A_thumb_DIP" name="Saf_thumb_DIP"/>
        <actuatorfrc actuator="A_index_ABD" name="Saf_index_ABD"/>
        <actuatorfrc actuator="A_index_MCP" name="Saf_index_MCP"/>
        <actuatorfrc actuator="A_middle_MCP" name="Saf_middle_MCP"/>
        <actuatorfrc actuator="A_ring_MCP" name="Saf_ring_MCP"/>
        <actuatorfrc actuator="A_pinky_ABD" name="Saf_pinky_ABD"/>
        <actuatorfrc actuator="A_pinky_MCP" name="Saf_pinky_MCP"/>
        <accelerometer site="thumb_IMU" name="S_thumb_IMU"/>
        <accelerometer site="index_IMU" name="S_index_IMU"/>
        <accelerometer site="middle_IMU" name="S_middle_IMU"/>
        <accelerometer site="ring_IMU" name="S_ring_IMU"/>
        <accelerometer site="pinky_IMU" name="S_pinky_IMU"/>
        <gyro site="thumb_IMU"/>
        <gyro site="index_IMU"/>
        <gyro site="middle_IMU"/>
        <gyro site="ring_IMU"/>
        <gyro site="pinky_IMU"/>
        <touch site="palm_thumb" name="S_palm_thumb"/>
        <touch site="palm_pinky" name="S_palm_pinky"/>
        <touch site="palm_side" name="S_palm_side"/>
        <touch site="palm_back" name="S_palm_back"/>
        <touch site="thumb_proximal" name="S_thumb_proximal"/>
        <touch site="thumb_medial" name="S_thumb_medial"/>
        <touch site="thumb_distal" name="S_thumb_distal"/>
        <touch site="index_proximal" name="S_index_proximal"/>
        <touch site="index_medial" name="S_index_medial"/>
        <touch site="index_distal" name="S_index_distal"/>
        <touch site="middle_proximal" name="S_middle_proximal"/>
        <touch site="middle_medial" name="S_middle_medial"/>
        <touch site="middle_distal" name="S_middle_distal"/>
        <touch site="ring_proximal" name="S_ring_proximal"/>
        <touch site="ring_medial" name="S_ring_medial"/>
        <touch site="ring_distal" name="S_ring_distal"/>
        <touch site="pinky_proximal" name="S_pinky_proximal"/>
        <touch site="pinky_medial" name="S_pinky_medial"/>
        <touch site="pinky_distal" name="S_pinky_distal"/>
    </sensor>
</mujoco>
