<mujoco model="MuJoCo Model">
    <!-- =================================================
	Copyright 2017 Vikash Kumar
	Model   :: ADROIT MANIPULATION PLATFORM (MuJoCoV2.0)
	Author  :: Vikash Kumar (vikashplus@gmail.com)
	Source  :: https://github.com/vikashplus/Adroit
	License :: Under Apache License, Version 2.0 (the "License"); you may not use this file except in compliance with the License. You may obtain a copy of the License at http://www.apache.org/licenses/LICENSE-2.0 Unless required by applicable law or agreed to in writing, software distributed under the License is distributed on an "AS IS" BASIS, WITHOUT WARRANTIES OR CONDITIONS OF ANY KIND, either express or implied. See the License for the specific language governing permissions and limitations under the License.
	Details :: Manipulator and Manipulation in High Dimensional Spaces. Vikash Kumar, Ph.D. Thesis, CSE, Univ. of Washington. 2016.
			:: With help from Shadow robot company (https://github.com/shadow-robot/sr_common)
====================================================== -©vk©-->
    <compiler angle="radian" meshdir="../meshes" />
    <option apirate="200" iterations="20"/>
    <size njmax="400" nconmax="100" nstack="600000" nuser_jnt="1" nuser_site="1" nuser_tendon="1" nuser_actuator="16" nuser_sensor="1"/>
    <visual>
        <global offwidth="1280" offheight="720"/>
        <quality shadowsize="4096"/>
        <map force="0.1" fogend="5"/>
    </visual>
    <default class="main">
        <default class="Adroit">
            <joint limited="true" margin="0.01" armature="0.001" damping="0.05" frictionloss="0.001"/>
            <geom friction="1 0.005 0.001" margin="0.0005"/>
            <site rgba="0.4 0.9 0.4 1"/>
            <tendon limited="true"/>
            <general ctrllimited="true" ctrlrange="-1 1"/>
            <default class="D_Touch">
                <site group="4" type="box" rgba="0.8 0.8 0.8 0.25"/>
            </default>
            <default class="DC_Hand">
                <geom conaffinity="0" group="4" material="MatColl"/>
            </default>
            <default class="D_Vizual">
                <geom type="mesh" contype="0" conaffinity="0" group="1" material="MatViz"/>
            </default>
            <default class="_D_Vizual">
                <geom type="mesh" contype="0" conaffinity="0" group="2" material="_MatViz"/>
            </default>
            <default class="wrist_visual">
                <geom type="mesh" contype="0" conaffinity="0" group="1" material="metal"/>
            </default>
            <default class="free">
                <joint type="free" limited="false" armature="0" damping="0"/>
            </default>
        </default>
    </default>
    <asset>
        <texture type="cube" name="texgeom" builtin="flat" mark="cross" rgb1="0.3 0.6 0.5" rgb2="0.3 0.6 0.5" width="127" height="762"/>
        <texture type="2d" name="texplane" builtin="checker" rgb1="0.2 0.3 0.4" rgb2="0.1 0.15 0.2" width="512" height="512"/>
        <material name="MatColl" specular="1" shininess="0.3" reflectance="0.5" rgba="0.4 0.5 0.6 1"/>
        <material name="MatViz" specular="0.75" shininess=".1" reflectance="0.5" rgba=".15 .15 .15 1"/>
        <material name="metal" reflectance="1.0" rgba="0.6 0.6 0.6 1.0" shininess="0.5" specular="1.0"/>
        <!-- <material name="MatViz" specular="0.75" shininess="0.1" reflectance="0.5" rgba="0.9 0.7 0.5 1"/> -->
        <!-- <material name="_MatViz" specular="0.75" shininess="0.1" reflectance="0.5" rgba="0.4 0.4 0.4 1"/> -->
        <material name="object" texture="texgeom"/>
        <material name="MatGnd" texture="texplane" texuniform="true" texrepeat="2 2" reflectance="0.5"/>
        <mesh name="forearm" file="forearm_electric.stl"/>
        <mesh name="forearm_cvx" file="forearm_electric_cvx.stl"/>
        <mesh name="wrist" file="wrist.stl" scale="0.001 0.001 0.001"/>
        <mesh name="palm" file="palm.stl" scale="0.001 0.001 0.001"/>
        <mesh name="knuckle" file="knuckle.stl" scale="0.001 0.001 0.001"/>
        <mesh name="F3" file="F3.stl" scale="0.001 0.001 0.001"/>
        <mesh name="F2" file="F2.stl" scale="0.001 0.001 0.001"/>
        <mesh name="F1" file="F1.stl" scale="0.001 0.001 0.001"/>
        <mesh name="lfmetacarpal" file="lfmetacarpal.stl" scale="0.001 0.001 0.001"/>
        <mesh name="TH3_z" file="TH3_z.stl" scale="0.001 0.001 0.001"/>
        <mesh name="TH2_z" file="TH2_z.stl" scale="0.001 0.001 0.001"/>
        <mesh name="TH1_z" file="TH1_z.stl" scale="0.001 0.001 0.001"/>
    </asset>
    <worldbody>
        <body name="hand mount" pos="0 0 0">
            <inertial pos="0 0 0" mass="0.1" diaginertia="0.001 0.001 0.001"/>
            <body name="forearm" childclass="Adroit" pos="0 0.01 0">
                <inertial pos="0.001 -0.002 0.29" quat="0.982037 -0.0160006 0 -0.188007" mass="4" diaginertia="0.01 0.01 0.0075"/>
                <geom name="V_forearm" class="D_Vizual" pos="0 -0.01 0.04" quat="0.707388 0 0 -0.706825" mesh="forearm"/>
                <geom name="C_forearm" class="DC_Hand" pos="0 -0.01 0.04" quat="0.707388 0 0 -0.706825" type="mesh" rgba="0.4 0.5 0.6 0.7" mesh="forearm_cvx"/>
                <body name="wrist" pos="0 0 0.256">
                    <inertial pos="0.003 0 0.016" quat="0.504234 0.49623 0.49523 0.504234" mass="0.3" diaginertia="0.001 0.001 0.001"/>
                    <joint name="WRJ1" pos="0 0 0" axis="0 1 0" range="-0.524 0.175" armature="0.005" damping="0.5" user="1123"/>
                    <geom name="V_wrist" class="wrist_visual" mesh="wrist"/>
                    <geom name="C_wrist" class="DC_Hand" size="0.015 0.01" quat="0.707107 0.707107 0 0" type="capsule" rgba="0.4 0.5 0.6 0.1"/>
                    <body name="palm" pos="0 0 0.034">
                        <inertial pos="0.006 0 0.036" quat="0.715833 0.0439898 0.0749825 0.692839" mass="0.3" diaginertia="0.001 0.001 0.001"/>
                        <joint name="WRJ0" pos="0 0 0" axis="1 0 0" range="-0.785 0.611" armature="0.005" damping="0.5" user="1122"/>
                        <geom name="V_palm" class="D_Vizual" mesh="palm"/>
                        <geom name="C_palm0" class="DC_Hand" size="0.032 0.0111 0.049" pos="0.011 0 0.038" type="box" rgba="0.4 0.5 0.6 0.1"/>
                        <geom name="C_palm1" class="DC_Hand" size="0.011 0.0111 0.025" pos="-0.032 0 0.014" type="box" rgba="0.4 0.5 0.6 0.1"/>
                        <site name="Tch_palm0top" class="D_Touch" pos="0.011 0 0.063" size="0.032 0.0111 0.024"/>
                        <site name="Tch_palm0bottom" class="D_Touch" pos="0.021 0 0.014" size="0.021 0.0111 0.025"/>
                        <site name="Tch_palm1" class="D_Touch" pos="-0.021 0 0.014" size="0.021 0.0111 0.025"/>
                        <body name="ffknuckle" pos="0.033 0 0.095">
                            <inertial pos="0 0 0" quat="0.520062 0.854102 0.00600072 -0.00300036" mass="0.008" diaginertia="1e-05 1e-05 1e-05"/>
                            <joint name="FFJ3" pos="0 0 0" axis="0 1 0" range="-0.436 0.436" user="1103"/>
                            <geom name="V_ffknuckle" class="D_Vizual" mesh="knuckle"/>
                            <body name="ffproximal" pos="0 0 0">
                                <inertial pos="0 0 0.023" quat="0.707095 -0.00400054 0.00400054 0.707095" mass="0.014" diaginertia="1e-05 1e-05 1e-05"/>
                                <joint name="FFJ2" pos="0 0 0" axis="1 0 0" range="0 1.571" user="1102"/>
                                <geom name="V_ffproximal" class="D_Vizual" mesh="F3"/>
                                <geom name="C_ffproximal" class="DC_Hand" size="0.01 0.0225" pos="0 0 0.0225" type="capsule"/>
                                <site name="Tch_ffproximal" class="D_Touch" pos="0 -0.004 0.0225" size="0.01 0.006 0.013"/>
                                <body name="ffmiddle" pos="0 0 0.045">
                                    <inertial pos="0 0 0.011" quat="0.707107 0 0 0.707107" mass="0.012" diaginertia="1e-05 1e-05 1e-05"/>
                                    <joint name="FFJ1" pos="0 0 0" axis="1 0 0" range="0 1.571" user="1101"/>
                                    <geom name="V_ffmiddle" class="D_Vizual" mesh="F2"/>
                                    <geom name="C_ffmiddle" class="DC_Hand" size="0.00805 0.0125" pos="0 0 0.0125" type="capsule"/>
                                    <site name="Tch_ffmiddle" class="D_Touch" pos="0 -0.004 0.0125" size="0.009 0.005 0.013"/>
                                    <body name="ffdistal" pos="0 0 0.025">
                                        <inertial pos="0 0 0.015" quat="0.7071 -0.00300043 0.00300043 0.7071" mass="0.01" diaginertia="1e-05 1e-05 1e-05"/>
                                        <joint name="FFJ0" pos="0 0 0" axis="1 0 0" range="0 1.571" user="1100"/>
                                        <geom name="V_ffdistal" class="D_Vizual" pos="0 0 0.001" mesh="F1"/>
                                        <geom name="C_ffdistal" class="DC_Hand" size="0.00705 0.012" pos="0 0 0.012" type="capsule" condim="4"/>
                                        <site name="S_fftip" pos="0 0 0.026" group="3"/>
                                        <site name="Tch_fftip" class="D_Touch" pos="0 -0.004 0.018" size="0.009 0.004 0.013"/>
                                    </body>
                                </body>
                            </body>
                        </body>
                        <body name="mfknuckle" pos="0.011 0 0.099">
                            <inertial pos="0 0 0" quat="0.520062 0.854102 0.00600072 -0.00300036" mass="0.008" diaginertia="1e-05 1e-05 1e-05"/>
                            <joint name="MFJ3" pos="0 0 0" axis="0 1 0" range="-0.436 0.436" user="1107"/>
                            <geom name="V_mfknuckle" class="D_Vizual" mesh="knuckle"/>
                            <body name="mfproximal" pos="0 0 0">
                                <inertial pos="0 0 0.023" quat="0.707095 -0.00400054 0.00400054 0.707095" mass="0.014" diaginertia="1e-05 1e-05 1e-05"/>
                                <joint name="MFJ2" pos="0 0 0" axis="1 0 0" range="0 1.571" user="1106"/>
                                <geom name="V_mfproximal" class="D_Vizual" mesh="F3"/>
                                <geom name="C_mfproximal" class="DC_Hand" size="0.01 0.0225" pos="0 0 0.0225" type="capsule"/>
                                <site name="Tch_mfproximal" class="D_Touch" pos="0 -0.004 0.0225" size="0.01 0.006 0.013"/>
                                <body name="mfmiddle" pos="0 0 0.045">
                                    <inertial pos="0 0 0.012" quat="0.707107 0 0 0.707107" mass="0.012" diaginertia="1e-05 1e-05 1e-05"/>
                                    <joint name="MFJ1" pos="0 0 0" axis="1 0 0" range="0 1.571" user="1105"/>
                                    <geom name="V_mfmiddle" class="D_Vizual" mesh="F2"/>
                                    <geom name="C_mfmiddle" class="DC_Hand" size="0.00805 0.0125" pos="0 0 0.0125" type="capsule"/>
                                    <site name="Tch_mfmiddle" class="D_Touch" pos="0 -0.004 0.0125" size="0.009 0.005 0.013"/>
                                    <body name="mfdistal" pos="0 0 0.025">
                                        <inertial pos="0 0 0.015" quat="0.7071 -0.00300043 0.00300043 0.7071" mass="0.01" diaginertia="1e-05 1e-05 1e-05"/>
                                        <joint name="MFJ0" pos="0 0 0" axis="1 0 0" range="0 1.571" user="1104"/>
                                        <geom name="V_mfdistal" class="D_Vizual" mesh="F1"/>
                                        <geom name="C_mfdistal" class="DC_Hand" size="0.00705 0.012" pos="0 0 0.012" type="capsule" condim="4"/>
                                        <site name="S_mftip" pos="0 0 0.026" group="3"/>
                                        <site name="Tch_mftip" class="D_Touch" pos="0 -0.004 0.018" size="0.009 0.004 0.013"/>
                                    </body>
                                </body>
                            </body>
                        </body>
                        <body name="rfknuckle" pos="-0.011 0 0.095">
                            <inertial pos="0 0 0" quat="0.520062 0.854102 0.00600072 -0.00300036" mass="0.008" diaginertia="1e-05 1e-05 1e-05"/>
                            <joint name="RFJ3" pos="0 0 0" axis="0 1 0" range="-0.436 0.436" user="1111"/>
                            <geom name="V_rfknuckle" class="D_Vizual" mesh="knuckle"/>
                            <body name="rfproximal" pos="0 0 0">
                                <inertial pos="0 0 0.023" quat="0.707095 -0.00400054 0.00400054 0.707095" mass="0.014" diaginertia="1e-05 1e-05 1e-05"/>
                                <joint name="RFJ2" pos="0 0 0" axis="1 0 0" range="0 1.571" user="1110"/>
                                <geom name="V_rfproximal" class="D_Vizual" mesh="F3"/>
                                <geom name="C_rfproximal" class="DC_Hand" size="0.01 0.0225" pos="0 0 0.0225" type="capsule"/>
                                <site name="Tch_rfproximal" class="D_Touch" pos="0 -0.004 0.0225" size="0.01 0.006 0.013"/>
                                <body name="rfmiddle" pos="0 0 0.045">
                                    <inertial pos="0 0 0.012" quat="0.707107 0 0 0.707107" mass="0.012" diaginertia="1e-05 1e-05 1e-05"/>
                                    <joint name="RFJ1" pos="0 0 0" axis="1 0 0" range="0 1.571" user="1109"/>
                                    <geom name="V_rfmiddle" class="D_Vizual" mesh="F2"/>
                                    <geom name="C_rfmiddle" class="DC_Hand" size="0.00805 0.0125" pos="0 0 0.0125" type="capsule"/>
                                    <site name="Tch_rfmiddle" class="D_Touch" pos="0 -0.004 0.0125" size="0.009 0.005 0.013"/>
                                    <body name="rfdistal" pos="0 0 0.025">
                                        <inertial pos="0 0 0.015" quat="0.7071 -0.00300043 0.00300043 0.7071" mass="0.01" diaginertia="1e-05 1e-05 1e-05"/>
                                        <joint name="RFJ0" pos="0 0 0" axis="1 0 0" range="0 1.571" user="1108"/>
                                        <geom name="V_rfdistal" class="D_Vizual" pos="0 0 0.001" mesh="F1"/>
                                        <geom name="C_rfdistal" class="DC_Hand" size="0.00705 0.012" pos="0 0 0.012" type="capsule" condim="4"/>
                                        <site name="S_rftip" pos="0 0 0.026" group="3"/>
                                        <site name="Tch_rftip" class="D_Touch" pos="0 -0.004 0.018" size="0.009 0.004 0.013"/>
                                    </body>
                                </body>
                            </body>
                        </body>
                        <body name="lfmetacarpal" pos="-0.017 0 0.044">
                            <inertial pos="-0.014 0.001 0.014" quat="0.709167 -0.0920216 -0.0630148 0.696164" mass="0.075" diaginertia="1e-05 1e-05 1e-05"/>
                            <joint name="LFJ4" pos="0 0 0" axis="0.570977 0 0.820966" range="0 0.698" user="1116"/>
                            <geom name="V_lfmetacarpal" class="D_Vizual" pos="-0.016 0 -0.023" mesh="lfmetacarpal"/>
                            <geom name="C_lfmetacarpal" class="DC_Hand" size="0.0095 0.0111 0.025" pos="-0.0165 0 0.01" type="box" rgba="0.4 0.5 0.6 0.2"/>
                            <site name="Tch_lfmetacarpal" class="D_Touch" pos="-0.0165 0 0.015" size="0.0095 0.0111 0.02"/>
                            <body name="lfknuckle" pos="-0.017 0 0.044">
                                <inertial pos="0 0 0" quat="0.520062 0.854102 0.00600072 -0.00300036" mass="0.008" diaginertia="1e-05 1e-05 1e-05"/>
                                <joint name="LFJ3" pos="0 0 0" axis="0 1 0" range="-0.436 0.436" user="1115"/>
                                <geom name="V_lfknuckle" class="D_Vizual" mesh="knuckle"/>
                                <body name="lfproximal" pos="0 0 0">
                                    <inertial pos="0 0 0.023" quat="0.707095 -0.00400054 0.00400054 0.707095" mass="0.014" diaginertia="1e-05 1e-05 1e-05"/>
                                    <joint name="LFJ2" pos="0 0 0" axis="1 0 0" range="0 1.571" user="1114"/>
                                    <geom name="V_lfproximal" class="D_Vizual" mesh="F3"/>
                                    <geom name="C_lfproximal" class="DC_Hand" size="0.01 0.0225" pos="0 0 0.0225" type="capsule"/>
                                    <site name="Tch_lfproximal" class="D_Touch" pos="0 -0.004 0.0225" size="0.01 0.006 0.013"/>
                                    <body name="lfmiddle" pos="0 0 0.045">
                                        <inertial pos="0 0 0.012" quat="0.707107 0 0 0.707107" mass="0.012" diaginertia="1e-05 1e-05 1e-05"/>
                                        <joint name="LFJ1" pos="0 0 0" axis="1 0 0" range="0 1.571" user="1113"/>
                                        <geom name="V_lfmiddle" class="D_Vizual" mesh="F2"/>
                                        <geom name="C_lfmiddle" class="DC_Hand" size="0.00805 0.0125" pos="0 0 0.0125" type="capsule"/>
                                        <site name="Tch_lfmiddle" class="D_Touch" pos="0 -0.004 0.0125" size="0.009 0.005 0.013"/>
                                        <body name="lfdistal" pos="0 0 0.025">
                                            <inertial pos="0 0 0.015" quat="0.7071 -0.00300043 0.00300043 0.7071" mass="0.01" diaginertia="1e-05 1e-05 1e-05"/>
                                            <joint name="LFJ0" pos="0 0 0" axis="1 0 0" range="0 1.571" user="1112"/>
                                            <geom name="V_lfdistal" class="D_Vizual" pos="0 0 0.001" mesh="F1"/>
                                            <geom name="C_lfdistal" class="DC_Hand" size="0.00705 0.012" pos="0 0 0.012" type="capsule" condim="4"/>
                                            <site name="S_lftip" pos="0 0 0.026" group="3"/>
                                            <site name="Tch_lftip" class="D_Touch" pos="0 -0.004 0.018" size="0.009 0.004 0.013"/>
                                        </body>
                                    </body>
                                </body>
                            </body>
                        </body>
                        <body name="thbase" pos="0.034 -0.009 0.029" quat="0.923956 0 0.382499 0">
                            <inertial pos="0 0 0" mass="0.01" diaginertia="1e-05 1e-05 1e-05"/>
                            <joint name="THJ4" pos="0 0 0" axis="0 0 -1" range="-1.047 1.047" user="1121"/>
                            <geom name="V_thbase" class="D_Vizual" size="0.001 0.001 0.001" type="box"/>
                            <body name="thproximal" pos="0 0 0">
                                <inertial pos="0 0 0.017" quat="0.981604 0 0.000999597 0.190923" mass="0.016" diaginertia="1e-05 1e-05 1e-05"/>
                                <joint name="THJ3" pos="0 0 0" axis="1 0 0" range="0 1.309" user="1120"/>
                                <geom name="V_thproximal" class="D_Vizual" mesh="TH3_z"/>
                                <geom name="C_thproximal" class="DC_Hand" size="0.013 0.019" pos="0 0 0.019" type="capsule" rgba="0.4 0.5 0.6 0.1"/>
                                <site name="Tch_thproxiaml" class="D_Touch" pos="-0.007 0 0.019" size="0.005 0.011 0.016"/>
                                <body name="thhub" pos="0 0 0.038">
                                    <inertial pos="0 0 0" mass="0.002" diaginertia="1e-05 1e-05 1e-05"/>
                                    <joint name="THJ2" pos="0 0 0" axis="1 0 0" range="-0.262 0.262" user="1119"/>
                                    <geom name="V_thhub" class="D_Vizual" size="0.001 0.001 0.001" type="box"/>
                                    <body name="thmiddle" pos="0 0 0">
                                        <inertial pos="0 0 0.016" quat="0.999971 -0.000999971 -0.00699979 0.00299991" mass="0.016" diaginertia="1e-05 1e-05 1e-05"/>
                                        <joint name="THJ1" pos="0 0 0" axis="0 1 0" range="-0.524 0.524" user="1118"/>
                                        <geom name="V_thmiddle" class="D_Vizual" mesh="TH2_z"/>
                                        <geom name="C_thmiddle" class="DC_Hand" size="0.011 0.016" pos="0 0 0.016" type="capsule"/>
                                        <site name="Tch_thmiddle" class="D_Touch" pos="-0.006 0 0.016" size="0.005 0.011 0.016"/>
                                        <body name="thdistal" pos="0 0 0.032">
                                            <inertial pos="0 0 0.016" quat="0.99887 -0.00499935 -0.0469939 0.00499935" mass="0.016" diaginertia="1e-05 1e-05 1e-05"/>
                                            <joint name="THJ0" pos="0 0 0" axis="0 1 0" range="-1.571 0" user="1117"/>
                                            <geom name="V_thdistal" class="D_Vizual" mesh="TH1_z"/>
                                            <geom name="C_thdistal" class="DC_Hand" size="0.00918 0.013" pos="0 0 0.013" type="capsule" condim="4"/>
                                            <site name="S_thtip" pos="0 0 0.0275" group="3"/>
                                            <site name="Tch_thtip" class="D_Touch" pos="-0.005 0 0.02" size="0.005 0.011 0.016"/>
                                        </body>
                                    </body>
                                </body>
                            </body>
                        </body>
                    </body>
                </body>
            </body>
        </body>
    </worldbody>
    <contact>
        <pair geom1="C_palm0" geom2="C_thdistal" condim="1"/>
        <pair geom1="C_ffproximal" geom2="C_mfproximal" condim="1"/>
        <pair geom1="C_ffproximal" geom2="C_thdistal" condim="1"/>
        <pair geom1="C_ffmiddle" geom2="C_thdistal" condim="1"/>
        <pair geom1="C_ffdistal" geom2="C_mfdistal" condim="1"/>
        <pair geom1="C_ffdistal" geom2="C_thdistal" condim="1"/>
        <pair geom1="C_mfproximal" geom2="C_rfproximal" condim="1"/>
        <pair geom1="C_mfproximal" geom2="C_thdistal" condim="1"/>
        <pair geom1="C_mfdistal" geom2="C_rfdistal" condim="1"/>
        <pair geom1="C_mfdistal" geom2="C_lfdistal" condim="1"/>
        <pair geom1="C_mfdistal" geom2="C_thdistal" condim="1"/>
        <pair geom1="C_rfproximal" geom2="C_lfproximal" condim="1"/>
        <pair geom1="C_rfmiddle" geom2="C_lfmiddle" condim="1"/>
        <pair geom1="C_rfmiddle" geom2="C_lfdistal" condim="1"/>
        <pair geom1="C_rfdistal" geom2="C_lfmiddle" condim="1"/>
        <pair geom1="C_rfdistal" geom2="C_lfdistal" condim="1"/>
        <pair geom1="C_rfdistal" geom2="C_lfdistal" condim="1"/>
        <pair geom1="C_rfdistal" geom2="C_thdistal" condim="1"/>
        <pair geom1="C_lfdistal" geom2="C_thdistal" condim="1"/>
    </contact>
    <tendon>
        <fixed name="T_WRJ1r" range="-0.032 0.032" user="1236">
            <joint joint="WRJ1" coef="0.018"/>
        </fixed>
        <fixed name="T_WRJ1l" range="-0.032 0.032" user="1237">
            <joint joint="WRJ1" coef="-0.018"/>
        </fixed>
        <fixed name="T_WRJ0u" range="-0.032 0.032" user="1236">
            <joint joint="WRJ0" coef="0.018"/>
        </fixed>
        <fixed name="T_WRJ0d" range="-0.032 0.032" user="1237">
            <joint joint="WRJ0" coef="-0.018"/>
        </fixed>
        <fixed name="T_FFJ3r" range="-0.018 0.018" user="1204">
            <joint joint="FFJ3" coef="0.01"/>
        </fixed>
        <fixed name="T_FFJ3l" range="-0.018 0.018" user="1205">
            <joint joint="FFJ3" coef="-0.01"/>
        </fixed>
        <fixed name="T_FFJ2u" range="-0.007 0.03" user="1202">
            <joint joint="FFJ2" coef="0.01"/>
        </fixed>
        <fixed name="T_FFJ2d" range="-0.03 0.007" user="1203">
            <joint joint="FFJ2" coef="-0.01"/>
        </fixed>
        <fixed name="T_FFJ1c" range="-0.001 0.001">
            <joint joint="FFJ0" coef="0.00705"/>
            <joint joint="FFJ1" coef="-0.00805"/>
        </fixed>
        <fixed name="T_FFJ1u" range="-0.007 0.03" user="1200">
            <joint joint="FFJ0" coef="0.00705"/>
            <joint joint="FFJ1" coef="0.00805"/>
        </fixed>
        <fixed name="T_FFJ1d" range="-0.03 0.007" user="1201">
            <joint joint="FFJ0" coef="-0.00705"/>
            <joint joint="FFJ1" coef="-0.00805"/>
        </fixed>
        <fixed name="T_MFJ3r" range="-0.018 0.018" user="1210">
            <joint joint="MFJ3" coef="0.01"/>
        </fixed>
        <fixed name="T_MFJ3l" range="-0.018 0.018" user="1211">
            <joint joint="MFJ3" coef="-0.01"/>
        </fixed>
        <fixed name="T_MFJ2u" range="-0.007 0.03" user="1208">
            <joint joint="MFJ2" coef="0.01"/>
        </fixed>
        <fixed name="T_MFJ2d" range="-0.03 0.007" user="1209">
            <joint joint="MFJ2" coef="-0.01"/>
        </fixed>
        <fixed name="T_MFJ1c" range="-0.001 0.001">
            <joint joint="MFJ0" coef="0.00705"/>
            <joint joint="MFJ1" coef="-0.00805"/>
        </fixed>
        <fixed name="T_MFJ1u" range="-0.007 0.03" user="1206">
            <joint joint="MFJ0" coef="0.00705"/>
            <joint joint="MFJ1" coef="0.00805"/>
        </fixed>
        <fixed name="T_MFJ1d" range="-0.03 0.007" user="1207">
            <joint joint="MFJ0" coef="-0.00705"/>
            <joint joint="MFJ1" coef="-0.00805"/>
        </fixed>
        <fixed name="T_RFJ3r" range="-0.018 0.018" user="1216">
            <joint joint="RFJ3" coef="0.01"/>
        </fixed>
        <fixed name="T_RFJ3l" range="-0.018 0.018" user="1217">
            <joint joint="RFJ3" coef="-0.01"/>
        </fixed>
        <fixed name="T_RFJ2u" range="-0.007 0.03" user="1214">
            <joint joint="RFJ2" coef="0.01"/>
        </fixed>
        <fixed name="T_RFJ2d" range="-0.03 0.007" user="1215">
            <joint joint="RFJ2" coef="-0.01"/>
        </fixed>
        <fixed name="T_RFJ1c" range="-0.001 0.001">
            <joint joint="RFJ0" coef="0.00705"/>
            <joint joint="RFJ1" coef="-0.00805"/>
        </fixed>
        <fixed name="T_RFJ1u" range="-0.007 0.03" user="1212">
            <joint joint="RFJ0" coef="0.00705"/>
            <joint joint="RFJ1" coef="0.00805"/>
        </fixed>
        <fixed name="T_RFJ1d" range="-0.03 0.007" user="1213">
            <joint joint="RFJ0" coef="-0.00705"/>
            <joint joint="RFJ1" coef="-0.00805"/>
        </fixed>
        <fixed name="T_LFJ4u" range="-0.007 0.03" user="1224">
            <joint joint="LFJ4" coef="0.01"/>
        </fixed>
        <fixed name="T_LFJ4d" range="-0.03 0.007" user="1225">
            <joint joint="LFJ4" coef="-0.01"/>
        </fixed>
        <fixed name="T_LFJ3r" range="-0.018 0.018" user="1222">
            <joint joint="LFJ3" coef="0.01"/>
        </fixed>
        <fixed name="T_LFJ3l" range="-0.018 0.018" user="1223">
            <joint joint="LFJ3" coef="-0.01"/>
        </fixed>
        <fixed name="T_LFJ2u" range="-0.007 0.03" user="1220">
            <joint joint="LFJ2" coef="0.01"/>
        </fixed>
        <fixed name="T_LFJ2d" range="-0.03 0.007" user="1221">
            <joint joint="LFJ2" coef="-0.01"/>
        </fixed>
        <fixed name="T_LFJ1c" range="-0.001 0.001">
            <joint joint="LFJ0" coef="0.00705"/>
            <joint joint="LFJ1" coef="-0.00805"/>
        </fixed>
        <fixed name="T_LFJ1u" range="-0.007 0.03" user="1218">
            <joint joint="LFJ0" coef="0.00705"/>
            <joint joint="LFJ1" coef="0.00805"/>
        </fixed>
        <fixed name="T_LFJ1d" range="-0.03 0.007" user="1219">
            <joint joint="LFJ0" coef="-0.00705"/>
            <joint joint="LFJ1" coef="-0.00805"/>
        </fixed>
        <fixed name="T_THJ4a" range="-0.018 0.018" user="1234">
            <joint joint="THJ4" coef="0.01636"/>
        </fixed>
        <fixed name="T_THJ4c" range="-0.018 0.018" user="1235">
            <joint joint="THJ4" coef="-0.01636"/>
        </fixed>
        <fixed name="T_THJ3u" range="-0.007 0.03" user="1232">
            <joint joint="THJ3" coef="0.01"/>
        </fixed>
        <fixed name="T_THJ3d" range="-0.03 0.007" user="1233">
            <joint joint="THJ3" coef="-0.01"/>
        </fixed>
        <fixed name="T_THJ2u" range="-0.018 0.018" user="1230">
            <joint joint="THJ2" coef="0.011"/>
        </fixed>
        <fixed name="T_THJ2d" range="-0.018 0.018" user="1231">
            <joint joint="THJ2" coef="-0.011"/>
        </fixed>
        <fixed name="T_THJ1r" range="-0.018 0.018" user="1228">
            <joint joint="THJ1" coef="0.011"/>
        </fixed>
        <fixed name="T_THJ1l" range="-0.018 0.018" user="1229">
            <joint joint="THJ1" coef="-0.011"/>
        </fixed>
        <fixed name="T_THJ0r" range="-0.03 0.007" user="1226">
            <joint joint="THJ0" coef="0.009"/>
        </fixed>
        <fixed name="T_THJ0l" range="-0.007 0.03" user="1227">
            <joint joint="THJ0" coef="-0.009"/>
        </fixed>
    </tendon>
    <actuator>
        <general name="A_WRJ1" class="Adroit" joint="WRJ1" ctrlrange="-0.52 0.17" biastype="affine" gainprm="10 0 0 0 0 0 0 0 0 0" biasprm="0 -10 0 0 0 0 0 0 0 0" user="2038 0 0 0 0 0 0 0 0 0 0 0 0 0 0 0"/>
        <general name="A_WRJ0" class="Adroit" joint="WRJ0" ctrlrange="-0.79 0.61" biastype="affine" gainprm="10 0 0 0 0 0 0 0 0 0" biasprm="0 -10 0 0 0 0 0 0 0 0" user="2036 0 0 0 0 0 0 0 0 0 0 0 0 0 0 0"/>
        <general name="A_FFJ3" class="Adroit" joint="FFJ3" ctrlrange="-0.44 0.44" biastype="affine" gainprm="1 0 0 0 0 0 0 0 0 0" biasprm="0 -1 0 0 0 0 0 0 0 0" user="2004 0 0 0 0 0 0 0 0 0 0 0 0 0 0 0"/>
        <general name="A_FFJ2" class="Adroit" joint="FFJ2" ctrlrange="0 1.6" biastype="affine" gainprm="1 0 0 0 0 0 0 0 0 0" biasprm="0 -1 0 0 0 0 0 0 0 0" user="2002 0 0 0 0 0 0 0 0 0 0 0 0 0 0 0"/>
        <general name="A_FFJ1" class="Adroit" joint="FFJ1" ctrlrange="0 1.6" biastype="affine" gainprm="1 0 0 0 0 0 0 0 0 0" biasprm="0 -1 0 0 0 0 0 0 0 0" user="2000 0 0 0 0 0 0 0 0 0 0 0 0 0 0 0"/>
        <general name="A_FFJ0" class="Adroit" joint="FFJ0" ctrlrange="0 1.6" biastype="affine" gainprm="1 0 0 0 0 0 0 0 0 0" biasprm="0 -1 0 0 0 0 0 0 0 0" user="2000 0 0 0 0 0 0 0 0 0 0 0 0 0 0 0"/>
        <general name="A_MFJ3" class="Adroit" joint="MFJ3" ctrlrange="-0.44 0.44" biastype="affine" gainprm="1 0 0 0 0 0 0 0 0 0" biasprm="0 -1 0 0 0 0 0 0 0 0" user="2010 0 0 0 0 0 0 0 0 0 0 0 0 0 0 0"/>
        <general name="A_MFJ2" class="Adroit" joint="MFJ2" ctrlrange="0 1.6" biastype="affine" gainprm="1 0 0 0 0 0 0 0 0 0" biasprm="0 -1 0 0 0 0 0 0 0 0" user="2008 0 0 0 0 0 0 0 0 0 0 0 0 0 0 0"/>
        <general name="A_MFJ1" class="Adroit" joint="MFJ1" ctrlrange="0 1.6" biastype="affine" gainprm="1 0 0 0 0 0 0 0 0 0" biasprm="0 -1 0 0 0 0 0 0 0 0" user="2006 0 0 0 0 0 0 0 0 0 0 0 0 0 0 0"/>
        <general name="A_MFJ0" class="Adroit" joint="MFJ0" ctrlrange="0 1.6" biastype="affine" gainprm="1 0 0 0 0 0 0 0 0 0" biasprm="0 -1 0 0 0 0 0 0 0 0" user="2006 0 0 0 0 0 0 0 0 0 0 0 0 0 0 0"/>
        <general name="A_RFJ3" class="Adroit" joint="RFJ3" ctrlrange="-0.44 0.44" biastype="affine" gainprm="1 0 0 0 0 0 0 0 0 0" biasprm="0 -1 0 0 0 0 0 0 0 0" user="2016 0 0 0 0 0 0 0 0 0 0 0 0 0 0 0"/>
        <general name="A_RFJ2" class="Adroit" joint="RFJ2" ctrlrange="0 1.6" biastype="affine" gainprm="1 0 0 0 0 0 0 0 0 0" biasprm="0 -1 0 0 0 0 0 0 0 0" user="2014 0 0 0 0 0 0 0 0 0 0 0 0 0 0 0"/>
        <general name="A_RFJ1" class="Adroit" joint="RFJ1" ctrlrange="0 1.6" biastype="affine" gainprm="1 0 0 0 0 0 0 0 0 0" biasprm="0 -1 0 0 0 0 0 0 0 0" user="2012 0 0 0 0 0 0 0 0 0 0 0 0 0 0 0"/>
        <general name="A_RFJ0" class="Adroit" joint="RFJ0" ctrlrange="0 1.6" biastype="affine" gainprm="1 0 0 0 0 0 0 0 0 0" biasprm="0 -1 0 0 0 0 0 0 0 0" user="2012 0 0 0 0 0 0 0 0 0 0 0 0 0 0 0"/>
        <general name="A_LFJ4" class="Adroit" joint="LFJ4" ctrlrange="0 0.7" biastype="affine" gainprm="1 0 0 0 0 0 0 0 0 0" biasprm="0 -1 0 0 0 0 0 0 0 0" user="2024 0 0 0 0 0 0 0 0 0 0 0 0 0 0 0"/>
        <general name="A_LFJ3" class="Adroit" joint="LFJ3" ctrlrange="-0.44 0.44" biastype="affine" gainprm="1 0 0 0 0 0 0 0 0 0" biasprm="0 -1 0 0 0 0 0 0 0 0" user="2022 0 0 0 0 0 0 0 0 0 0 0 0 0 0 0"/>
        <general name="A_LFJ2" class="Adroit" joint="LFJ2" ctrlrange="0 1.6" biastype="affine" gainprm="1 0 0 0 0 0 0 0 0 0" biasprm="0 -1 0 0 0 0 0 0 0 0" user="2020 0 0 0 0 0 0 0 0 0 0 0 0 0 0 0"/>
        <general name="A_LFJ1" class="Adroit" joint="LFJ1" ctrlrange="0 1.6" biastype="affine" gainprm="1 0 0 0 0 0 0 0 0 0" biasprm="0 -1 0 0 0 0 0 0 0 0" user="2018 0 0 0 0 0 0 0 0 0 0 0 0 0 0 0"/>
        <general name="A_LFJ0" class="Adroit" joint="LFJ0" ctrlrange="0 1.6" biastype="affine" gainprm="1 0 0 0 0 0 0 0 0 0" biasprm="0 -1 0 0 0 0 0 0 0 0" user="2018 0 0 0 0 0 0 0 0 0 0 0 0 0 0 0"/>
        <general name="A_THJ4" class="Adroit" joint="THJ4" biastype="affine" gainprm="1 0 0 0 0 0 0 0 0 0" biasprm="0 -1 0 0 0 0 0 0 0 0" user="2034 0 0 0 0 0 0 0 0 0 0 0 0 0 0 0"/>
        <general name="A_THJ3" class="Adroit" joint="THJ3" ctrlrange="0 1.3" biastype="affine" gainprm="1 0 0 0 0 0 0 0 0 0" biasprm="0 -1 0 0 0 0 0 0 0 0" user="2032 0 0 0 0 0 0 0 0 0 0 0 0 0 0 0"/>
        <general name="A_THJ2" class="Adroit" joint="THJ2" ctrlrange="-0.26 0.26" biastype="affine" gainprm="1 0 0 0 0 0 0 0 0 0" biasprm="0 -1 0 0 0 0 0 0 0 0" user="2030 0 0 0 0 0 0 0 0 0 0 0 0 0 0 0"/>
        <general name="A_THJ1" class="Adroit" joint="THJ1" ctrlrange="-0.52 0.52" biastype="affine" gainprm="1 0 0 0 0 0 0 0 0 0" biasprm="0 -1 0 0 0 0 0 0 0 0" user="2028 0 0 0 0 0 0 0 0 0 0 0 0 0 0 0"/>
        <general name="A_THJ0" class="Adroit" joint="THJ0" ctrlrange="-1.571 0" biastype="affine" gainprm="1 0 0 0 0 0 0 0 0 0" biasprm="0 -1 0 0 0 0 0 0 0 0" user="2026 0 0 0 0 0 0 0 0 0 0 0 0 0 0 0"/>
    </actuator>
    <sensor>
        <jointpos joint="WRJ1" name="Sjp_WRJ1"/>
        <jointpos joint="WRJ0" name="Sjp_WRJ0"/>
        <jointpos joint="FFJ3" name="Sjp_FFJ3"/>
        <jointpos joint="FFJ2" name="Sjp_FFJ2"/>
        <jointpos joint="FFJ1" name="Sjp_FFJ1"/>
        <jointpos joint="FFJ0" name="Sjp_FFJ0"/>
        <jointpos joint="MFJ3" name="Sjp_MFJ3"/>
        <jointpos joint="MFJ2" name="Sjp_MFJ2"/>
        <jointpos joint="MFJ1" name="Sjp_MFJ1"/>
        <jointpos joint="MFJ0" name="Sjp_MFJ0"/>
        <jointpos joint="RFJ3" name="Sjp_RFJ3"/>
        <jointpos joint="RFJ2" name="Sjp_RFJ2"/>
        <jointpos joint="RFJ1" name="Sjp_RFJ1"/>
        <jointpos joint="RFJ0" name="Sjp_RFJ0"/>
        <jointpos joint="LFJ4" name="Sjp_LFJ4"/>
        <jointpos joint="LFJ3" name="Sjp_LFJ3"/>
        <jointpos joint="LFJ2" name="Sjp_LFJ2"/>
        <jointpos joint="LFJ1" name="Sjp_LFJ1"/>
        <jointpos joint="LFJ0" name="Sjp_LFJ0"/>
        <jointpos joint="THJ4" name="Sjp_THJ4"/>
        <jointpos joint="THJ3" name="Sjp_THJ3"/>
        <jointpos joint="THJ2" name="Sjp_THJ2"/>
        <jointpos joint="THJ1" name="Sjp_THJ1"/>
        <jointpos joint="THJ0" name="Sjp_THJ0"/>
        <touch site="Tch_palm0top" name="ST_Tch_palm0top"/>
        <touch site="Tch_palm0bottom" name="ST_Tch_palm0bottom"/>
        <touch site="Tch_palm1" name="ST_Tch_palm1"/>
        <touch site="Tch_fftip" name="ST_Tch_fftip"/>
        <touch site="Tch_fftip" name="ST_Tch_ffmiddle"/>
        <touch site="Tch_ffproximal" name="ST_Tch_ffproximal"/>
        <touch site="Tch_mftip" name="ST_Tch_mftip"/>
        <touch site="Tch_mftip" name="ST_Tch_mfmiddle"/>
        <touch site="Tch_mfproximal" name="ST_Tch_mfproximal"/>
        <touch site="Tch_rftip" name="ST_Tch_rftip"/>
        <touch site="Tch_rftip" name="ST_Tch_rfmiddle"/>
        <touch site="Tch_rfproximal" name="ST_Tch_rfproximal"/>
        <touch site="Tch_lftip" name="ST_Tch_lftip"/>
        <touch site="Tch_lftip" name="ST_Tch_lfmiddle"/>
        <touch site="Tch_lfproximal" name="ST_Tch_lfproximal"/>
        <touch site="Tch_lfmetacarpal" name="ST_Tch_lfmetacarpal"/>
        <touch site="Tch_thtip" name="ST_Tch_thtip"/>
    </sensor>
</mujoco>
